<?xml version="1.0" ?>
<robot name="x500-Base">
  <joint name="x500-Base__rotor_0_joint" type="revolute">
    <parent link="x500-Base__base_link"/>
    <child link="x500-Base__rotor_0"/>
    <origin xyz="0.174 -0.174  0.3" rpy="0 0 0"/>
    <axis xyz="0 0 1"/>
    <limit lower="-1e+16" upper="1e+16" effort="1.0" velocity="1.0"/>
  </joint>
  <joint name="x500-Base__rotor_1_joint" type="revolute">
    <parent link="x500-Base__base_link"/>
    <child link="x500-Base__rotor_1"/>
    <origin xyz="-0.174  0.174  0.3" rpy="0 0 0"/>
    <axis xyz="0 0 1"/>
    <limit lower="-1e+16" upper="1e+16" effort="1.0" velocity="1.0"/>
  </joint>
  <joint name="x500-Base__rotor_2_joint" type="revolute">
    <parent link="x500-Base__base_link"/>
    <child link="x500-Base__rotor_2"/>
    <origin xyz="0.174 0.174 0.3" rpy="0 0 0"/>
    <axis xyz="0 0 1"/>
    <limit lower="-1e+16" upper="1e+16" effort="1.0" velocity="1.0"/>
  </joint>
  <joint name="x500-Base__rotor_3_joint" type="revolute">
    <parent link="x500-Base__base_link"/>
    <child link="x500-Base__rotor_3"/>
    <origin xyz="-0.174 -0.174  0.3" rpy="0 0 0"/>
    <axis xyz="0 0 1"/>
    <limit lower="-1e+16" upper="1e+16" effort="1.0" velocity="1.0"/>
  </joint>
  <link name="x500-Base__base_link">
    <inertial>
      <mass value="2.0"/>
      <origin xyz="0 0 0" rpy="0 0 0"/>
      <inertia ixx="0.02166666666666667" ixy="0" ixz="0" iyy="0.02166666666666667" iyz="0" izz="0.04000000000000001"/>
    </inertial>
    <collision name="x500-Base__base_link_collision_0">
      <origin xyz="0    0    0.247" rpy="0 0 0"/>
      <geometry>
        <box size="0.35355339059327373 0.35355339059327373 0.05"/>
      </geometry>
    </collision>
    <collision name="x500-Base__base_link_collision_1">
      <origin xyz="0    -0.098  0.117" rpy="-0.35  0    0"/>
      <geometry>
        <box size="0.015 0.015 0.21"/>
      </geometry>
    </collision>
    <collision name="x500-Base__base_link_collision_2">
      <origin xyz="0    0.098 0.117" rpy="0.35 0   0"/>
      <geometry>
        <box size="0.015 0.015 0.21"/>
      </geometry>
    </collision>
    <collision name="x500-Base__base_link_collision_3">
      <origin xyz="0     -0.132   0.0205" rpy="0 0 0"/>
      <geometry>
        <box size="0.25 0.015 0.015"/>
      </geometry>
    </collision>
    <collision name="x500-Base__base_link_collision_4">
      <origin xyz="0     0.132  0.0205" rpy="0 0 0"/>
      <geometry>
        <box size="0.25 0.015 0.015"/>
      </geometry>
    </collision>
    <visual name="x500-Base__base_link_visual">
      <origin xyz="0    0    0.265" rpy="0       0      -3.14159"/>
      <geometry>
        <mesh filename="package://x500/meshes/NXP-HGD-CF.dae" scale="1 1 1"/>
      </geometry>
    </visual>
    <visual name="x500-Base__5010_motor_base_0">
      <origin xyz="0.174 0.174 0.272" rpy="0    0   -0.45"/>
      <geometry>
        <mesh filename="package://x500/meshes/5010Base.dae" scale="1 1 1"/>
      </geometry>
    </visual>
    <visual name="x500-Base__5010_motor_base_1">
      <origin xyz="-0.174  0.174  0.272" rpy="0    0   -0.45"/>
      <geometry>
        <mesh filename="package://x500/meshes/5010Base.dae" scale="1 1 1"/>
      </geometry>
    </visual>
    <visual name="x500-Base__5010_motor_base_2">
      <origin xyz="0.174 -0.174  0.272" rpy="0    0   -0.45"/>
      <geometry>
        <mesh filename="package://x500/meshes/5010Base.dae" scale="1 1 1"/>
      </geometry>
    </visual>
    <visual name="x500-Base__5010_motor_base_3">
      <origin xyz="-0.174 -0.174  0.272" rpy="0    0   -0.45"/>
      <geometry>
        <mesh filename="package://x500/meshes/5010Base.dae" scale="1 1 1"/>
      </geometry>
    </visual>
  </link>
  <link name="x500-Base__rotor_0">
    <inertial>
      <mass value="0.016076923076923075"/>
      <origin xyz="0 0 0" rpy="0 0 0"/>
      <inertia ixx="3.8464910483993325e-07" ixy="0" ixz="0" iyy="2.6115851691700804e-05" iyz="0" izz="2.649858234714004e-05"/>
    </inertial>
    <collision name="x500-Base__rotor_0_collision">
      <origin xyz="0 0 0" rpy="0 0 0"/>
      <geometry>
        <box size="0.2792307692307692 0.016923076923076923 0.0008461538461538462"/>
      </geometry>
    </collision>
    <visual name="x500-Base__rotor_0_visual">
      <origin xyz="-0.022   -0.14638 -0.016" rpy="0 0 0"/>
      <geometry>
        <mesh filename="package://x500/meshes/1345_prop_ccw.stl" scale="0.8461538461538461 0.8461538461538461 0.8461538461538461"/>
      </geometry>
    </visual>
    <visual name="x500-Base__rotor_0_visual_motor_bell">
      <origin xyz="0     0    -0.032" rpy="0 0 0"/>
      <geometry>
        <mesh filename="package://x500/meshes/5010Bell.dae" scale="1 1 1"/>
      </geometry>
    </visual>
  </link>
  <link name="x500-Base__rotor_1">
    <inertial>
      <mass value="0.016076923076923075"/>
      <origin xyz="0 0 0" rpy="0 0 0"/>
      <inertia ixx="3.8464910483993325e-07" ixy="0" ixz="0" iyy="2.6115851691700804e-05" iyz="0" izz="2.649858234714004e-05"/>
    </inertial>
    <collision name="x500-Base__rotor_1_collision">
      <origin xyz="0 0 0" rpy="0 0 0"/>
      <geometry>
        <box size="0.2792307692307692 0.016923076923076923 0.0008461538461538462"/>
      </geometry>
    </collision>
    <visual name="x500-Base__rotor_1_visual">
      <origin xyz="-0.022   -0.14638 -0.016" rpy="0 0 0"/>
      <geometry>
        <mesh filename="package://x500/meshes/1345_prop_ccw.stl" scale="0.8461538461538461 0.8461538461538461 0.8461538461538461"/>
      </geometry>
    </visual>
    <visual name="x500-Base__rotor_1_visual_motor_top">
      <origin xyz="0     0    -0.032" rpy="0 0 0"/>
      <geometry>
        <mesh filename="package://x500/meshes/5010Bell.dae" scale="1 1 1"/>
      </geometry>
    </visual>
  </link>
  <link name="x500-Base__rotor_2">
    <inertial>
      <mass value="0.016076923076923075"/>
      <origin xyz="0 0 0" rpy="0 0 0"/>
      <inertia ixx="3.8464910483993325e-07" ixy="0" ixz="0" iyy="2.6115851691700804e-05" iyz="0" izz="2.649858234714004e-05"/>
    </inertial>
    <collision name="x500-Base__rotor_2_collision">
      <origin xyz="0 0 0" rpy="0 0 0"/>
      <geometry>
        <box size="0.2792307692307692 0.016923076923076923 0.0008461538461538462"/>
      </geometry>
    </collision>
    <visual name="x500-Base__rotor_2_visual">
      <origin xyz="-0.022   -0.14638 -0.016" rpy="0 0 0"/>
      <geometry>
        <mesh filename="package://x500/meshes/1345_prop_cw.stl" scale="0.8461538461538461 0.8461538461538461 0.8461538461538461"/>
      </geometry>
    </visual>
    <visual name="x500-Base__rotor_2_visual_motor_top">
      <origin xyz="0     0    -0.032" rpy="0 0 0"/>
      <geometry>
        <mesh filename="package://x500/meshes/5010Bell.dae" scale="1 1 1"/>
      </geometry>
    </visual>
  </link>
  <link name="x500-Base__rotor_3">
    <inertial>
      <mass value="0.016076923076923075"/>
      <origin xyz="0 0 0" rpy="0 0 0"/>
      <inertia ixx="3.8464910483993325e-07" ixy="0" ixz="0" iyy="2.6115851691700804e-05" iyz="0" izz="2.649858234714004e-05"/>
    </inertial>
    <collision name="x500-Base__rotor_3_collision">
      <origin xyz="0 0 0" rpy="0 0 0"/>
      <geometry>
        <box size="0.2792307692307692 0.016923076923076923 0.0008461538461538462"/>
      </geometry>
    </collision>
    <visual name="x500-Base__rotor_3_visual">
      <origin xyz="-0.022   -0.14638 -0.016" rpy="0 0 0"/>
      <geometry>
        <mesh filename="package://x500/meshes/1345_prop_cw.stl" scale="0.8461538461538461 0.8461538461538461 0.8461538461538461"/>
      </geometry>
    </visual>
    <visual name="x500-Base__rotor_3_visual_motor_top">
      <origin xyz="0     0    -0.032" rpy="0 0 0"/>
      <geometry>
        <mesh filename="package://x500/meshes/5010Bell.dae" scale="1 1 1"/>
      </geometry>
    </visual>
  </link>
</robot>
